{"owner": {"display_name": "anonymous", "reputation": 6831, "profile_image": "https://i.stack.imgur.com/2JhR5.jpg?s=128&g=1", "user_id": 2063361, "user_type": "registered", "accept_rate": 75, "link": "http://stackoverflow.com/users/2063361/anonymous"}, "link": "http://stackoverflow.com/questions/39835471/pyodbc-python-3-error-while-executing-query-ubuntu-14-04", "tags": ["python", "python-3.x", "ubuntu-14.04", "pyodbc", "netezza"], "creation_date": 1475509478, "score": 1, "last_edit_date": 1475510459, "is_answered": false, "view_count": 56, "last_activity_date": 1477469724, "question_id": 39835471, "answer_count": 0, "title": "PyODBC Python 3 error while executing query (Ubuntu 14.04)"}