{"last_activity_date": 1477482995, "owner": {"display_name": "Menas A.Ismail", "reputation": 1, "profile_image": "https://www.gravatar.com/avatar/666894c9bc51706380f38b969c541942?s=128&d=identicon&r=PG&f=1", "user_id": 7074699, "user_type": "registered", "link": "http://stackoverflow.com/users/7074699/menas-a-ismail"}, "is_answered": false, "answer_count": 0, "creation_date": 1477482995, "score": 0, "title": "Error in creating many2one field with odoo", "tags": ["python", "postgresql", "odoo-8"], "view_count": 18, "question_id": 40261653, "link": "http://stackoverflow.com/questions/40261653/error-in-creating-many2one-field-with-odoo"}