{"owner": {"display_name": "Alejandro", "reputation": 130, "profile_image": "https://www.gravatar.com/avatar/519d6807561b89f6cbb1b3cfd6cb5aa0?s=128&d=identicon&r=PG", "user_id": 2100783, "user_type": "registered", "accept_rate": 75, "link": "http://stackoverflow.com/users/2100783/alejandro"}, "link": "http://stackoverflow.com/questions/40286681/pyodbc-error-hy000-the-driver-did-not-supply-an-error", "tags": ["python", "mysql", "pyodbc"], "creation_date": 1477576949, "score": 1, "last_edit_date": 1477577475, "is_answered": true, "view_count": 15, "last_activity_date": 1477582223, "question_id": 40286681, "accepted_answer_id": 40288662, "answer_count": 1, "title": "pyodbc.Error: (&#39;HY000&#39;, &#39;The driver did not supply an error!&#39;)"}